Workbook

Sheet Synthèse
A1: Migration vers la nouvelle documentation DataMa
A2: Toutes les valeurs ci-dessous sont des formules : elles se mettent à jour quand vous remplissez les autres onglets.
A4: Pages
A5: Pages actuelles | B5: =COUNTA('Mapping des pages'!$B$5:$B$218) -> 214
A6: Pages non migrées | B6: =COUNTIF('Mapping des pages'!$I$5:$I$218,"— (non migrée)") -> 5
A7: Pages de la nouvelle doc | B7: =COUNTA('Pages cibles'!$B$5:$B$75) -> 71
A8: dont nouvelles pages à écrire | B8: =COUNTIF('Pages cibles'!$H$5:$H$75,"Nouvelle page à écrire") -> 5
A10: Validation du mapping
A11: À valider | B11: =COUNTIF('Mapping des pages'!$O$5:$O$218,"À valider") -> 214
A12: Validé | B12: =COUNTIF('Mapping des pages'!$O$5:$O$218,"Validé") -> 0
A13: Refusé | B13: =COUNTIF('Mapping des pages'!$O$5:$O$218,"Refusé") -> 0
A14: À revoir | B14: =COUNTIF('Mapping des pages'!$O$5:$O$218,"À revoir") -> 0
A15: Avancement (pages tranchées) | B15: =IF(B5=0,0,(B12+B13)/B5) -> 0
A17: Images
A18: Images actuelles | B18: =SUM('Mapping des pages'!$F$5:$F$218) -> 735
A19: dont GIF | B19: =SUM('Mapping des pages'!$G$5:$G$218) -> 128
A20: Images cibles (proposé) | B20: =SUM('Mapping des pages'!$N$5:$N$218) -> 176
A21: Réduction | B21: =IF(B18=0,0,1-B20/B18) -> 0.76054422
A23: Tips of the week
A24: Tips actuels (EN) | B24: =COUNTA('Tips of the week'!$C$5:$C$119) -> 115
A25: Proposition : Garder | B25: =COUNTIF('Tips of the week'!$E$5:$E$119,"Garder") -> 41
A26: Proposition : Archiver | B26: =COUNTIF('Tips of the week'!$E$5:$E$119,"Archiver") -> 45
A27: Proposition : À vérifier | B27: =COUNTIF('Tips of the week'!$E$5:$E$119,"À vérifier") -> 29
A28: Décision : Garder | B28: =COUNTIF('Tips of the week'!$G$5:$G$119,"Garder") -> 41
A29: Décision : Archiver | B29: =COUNTIF('Tips of the week'!$G$5:$G$119,"Archiver") -> 45
A30: Décision : À décider | B30: =COUNTIF('Tips of the week'!$G$5:$G$119,"À décider") -> 29
A32: Mode d’emploi
A33: 1. Onglet « Mapping des pages » : une ligne par page actuelle. Validez la nouvelle page proposée (colonne Décision).
A34: 2. Si la page cible ne convient pas : Refusé ou À revoir, et la bonne page cible dans la colonne Commentaire.
A35: 3. Ajustez si besoin le nombre d’images à garder (colonne Images cibles, en bleu) : la synthèse se recalcule.
A36: 4. Onglet « Pages cibles » : la liste des pages de la nouvelle doc, avec leurs sources ; validez la structure.
A37: 5. Onglet « Tips of the week » : Garder ou Archiver chaque tip ; « À décider » pour ceux qui demandent une vérification produit.
A38: Cellules jaunes = à remplir. Le reste est calculé ou issu de l’inventaire de la doc actuelle (repo docs, branche master).
A39: Hypothèses : les environnements de chaque type de slide (Pivot, Journey = web app ; Spreadsheet = BI) et la répartition des réglages story / visuel sont provisoires.

Sheet Mapping des pages
A1: Mapping des pages : ancienne doc → nouvelle doc
A2: Une ligne par page actuelle. À remplir : colonnes jaunes (Images cibles, Décision, Commentaire). Décision : Validé / Refusé / À revoir. Si refusé, indiquez la bonne page cible en commentaire.
A4: # | B4: Ancien chemin | C4: Titre actuel | D4: Dans le menu actuel | E4: Mots | F4: Images | G4: dont GIF | H4: Rubrique cible | I4: Nouvelle page | J4: Titre cible | K4: Environnements | L4: Traitement proposé | M4: Proposition images | N4: Images cibles (proposé) | O4: Décision | P4: Commentaire / autre page cible
A5: 1 | B5: Privacy_Policy.md | C5: PRIVACY POLICY | D5: Non | E5: 2803 | F5: 0 | G5: 0 | H5: Legal (footer) | I5: /legal/privacy-policy/ | J5: Privacy policy | K5: Tous | L5: Fusionner les doublons ; garder les anciennes URL (fiches marketplace) | M5: — | N5: 0 | O5: À valider
A6: 2 | B6: core_app.md | C6: Core app | D6: Non | E6: 0 | F6: 0 | G6: 0 | H6: — | I6: — (non migrée) | J6: — | K6: — | L6: Ne pas migrer : page vide | M6: Aucune (page non migrée) | N6: 0 | O6: À valider
A7: 3 | B7: core_app/licence_terms.md | C7: TERMS OF SERVICE | D7: Non | E7: 4530 | F7: 0 | G7: 0 | H7: Legal (footer) | I7: /legal/terms-of-service/ | J7: Terms of Service | K7: Tous | L7: Fusionner les doublons ; garder les anciennes URL (fiches marketplace) | M7: — | N7: 0 | O7: À valider
A8: 4 | B8: core_app/licence_terms/privacy_policy.md | C8: PRIVACY POLICY | D8: Non | E8: 2803 | F8: 0 | G8: 0 | H8: Legal (footer) | I8: /legal/privacy-policy/ | J8: Privacy policy | K8: Tous | L8: Fusionner les doublons ; garder les anciennes URL (fiches marketplace) | M8: — | N8: 0 | O8: À valider
A9: 5 | B9: core_app/licence_terms/terms_of_service.md | C9: TERMS OF SERVICE | D9: Non | E9: 4532 | F9: 0 | G9: 0 | H9: Legal (footer) | I9: /legal/terms-of-service/ | J9: Terms of Service | K9: Tous | L9: Fusionner les doublons ; garder les anciennes URL (fiches marketplace) | M9: — | N9: 0 | O9: À valider
A10: 6 | B10: core_app/new/Datama_on_premise.md | C10: Datama on Premise | D10: Oui | E10: 122 | F10: 0 | G10: 0 | H10: — | I10: — (non migrée) | J10: — | K10: — | L10: Ne pas migrer : On-premise retiré de la doc | M10: Aucune (page non migrée) | N10: 0 | O10: À valider
A11: 7 | B11: core_app/new/admin/Power_BI_privacy_policy.md | C11: Datama Power BI Extension Privacy Policy | D11: Non | E11: 601 | F11: 0 | G11: 0 | H11: Legal (footer) | I11: /legal/privacy/power-bi/ | J11: Privacy policy › Power BI | K11: Power BI | L11: Migrer tel quel ; garder l’ancienne URL (AppSource) | M11: — | N11: 0 | O11: À valider
A12: 8 | B12: core_app/new/admin/licence_terms.md | C12: TERMS OF SERVICE | D12: Non | E12: 4530 | F12: 0 | G12: 0 | H12: Legal (footer) | I12: /legal/terms-of-service/ | J12: Terms of Service | K12: Tous | L12: Fusionner les doublons ; garder les anciennes URL (fiches marketplace) | M12: — | N12: 0 | O12: À valider
A13: 9 | B13: core_app/new/admin/privacy_policy.md | C13: PRIVACY POLICY | D13: Oui | E13: 2803 | F13: 0 | G13: 0 | H13: Legal (footer) | I13: /legal/privacy-policy/ | J13: Privacy policy | K13: Tous | L13: Fusionner les doublons ; garder les anciennes URL (fiches marketplace) | M13: — | N13: 0 | O13: À valider
A14: 10 | B14: core_app/new/admin/terms_of_service.md | C14: TERMS OF SERVICE | D14: Oui | E14: 4532 | F14: 0 | G14: 0 | H14: Legal (footer) | I14: /legal/terms-of-service/ | J14: Terms of Service | K14: Tous | L14: Fusionner les doublons ; garder les anciennes URL (fiches marketplace) | M14: — | N14: 0 | O14: À valider
A15: 11 | B15: core_app/new/assess/assess.md | C15: Datama Assess | D15: Oui | E15: 145 | F15: 2 | G15: 0 | H15: Slide types | I15: /slide-types/assess/ | J15: Assess | K15: Tous | L15: Fusionner | M15: Supprimer les captures d’interface ; 1 visuel d’ensemble si indispensable | N15: 1 | O15: À valider
A16: 12 | B16: core_app/new/assess/assess_header.md | C16: Assess (Sub)Header | D16: Oui | E16: 40 | F16: 1 | G16: 0 | H16: Slide types | I16: /slide-types/assess/visual-settings/ | J16: Assess › Visual settings | K16: Tous | L16: Fusionner | M16: Supprimer les captures d’interface ; 1 visuel d’ensemble si indispensable | N16: 1 | O16: À valider
... A218: 214 | B218: web_application.md | C218: Web application | D218: Non | E218: 0 | F218: 0 | G218: 0 | H218: — | I218: — (non migrée) | J218: — | K218: — | L218: Ne pas migrer : page vide | M218: Aucune (page non migrée) | N218: 0 | O218: À valider

Sheet Pages cibles
A1: Pages de la nouvelle doc et leurs sources
A2: Calculé depuis l’onglet Mapping des pages (formules). Seule la colonne Décision est à remplir.
A4: Rubrique | B4: Nouvelle page | C4: Titre | D4: Environnements | E4: Pages sources | F4: Images actuelles | G4: Images cibles | H4: Type | I4: Décision | J4: Commentaire
A5: Accueil | B5: / | C5: Home | D5: Tous | E5: =COUNTIF('Mapping des pages'!$I$5:$I$218,B5) -> 1 | F5: =SUMIF('Mapping des pages'!$I$5:$I$218,B5,'Mapping des pages'!$F$5:$F$218) -> 0 | G5: =SUMIF('Mapping des pages'!$I$5:$I$218,B5,'Mapping des pages'!$N$5:$N$218) -> 0 | H5: =IF(E5=0,"Nouvelle page à écrire","Migration") -> Migration | I5: À valider
A6: Get started | B6: /start/what-is-datama/ | C6: What is Datama | D6: Tous | E6: =COUNTIF('Mapping des pages'!$I$5:$I$218,B6) -> 1 | F6: =SUMIF('Mapping des pages'!$I$5:$I$218,B6,'Mapping des pages'!$F$5:$F$218) -> 2 | G6: =SUMIF('Mapping des pages'!$I$5:$I$218,B6,'Mapping des pages'!$N$5:$N$218) -> 1 | H6: =IF(E6=0,"Nouvelle page à écrire","Migration") -> Migration | I6: À valider
A7: Get started | B7: /start/quick-start/ | C7: Quick start | D7: Tous | E7: =COUNTIF('Mapping des pages'!$I$5:$I$218,B7) -> 1 | F7: =SUMIF('Mapping des pages'!$I$5:$I$218,B7,'Mapping des pages'!$F$5:$F$218) -> 9 | G7: =SUMIF('Mapping des pages'!$I$5:$I$218,B7,'Mapping des pages'!$N$5:$N$218) -> 1 | H7: =IF(E7=0,"Nouvelle page à écrire","Migration") -> Migration | I7: À valider
A8: Get started | B8: /start/key-concepts/ | C8: Key concepts | D8: Tous | E8: =COUNTIF('Mapping des pages'!$I$5:$I$218,B8) -> 0 | F8: =SUMIF('Mapping des pages'!$I$5:$I$218,B8,'Mapping des pages'!$F$5:$F$218) -> 0 | G8: =SUMIF('Mapping des pages'!$I$5:$I$218,B8,'Mapping des pages'!$N$5:$N$218) -> 0 | H8: =IF(E8=0,"Nouvelle page à écrire","Migration") -> Nouvelle page à écrire | I8: À valider
A9: Prepare your data | B9: /data/ | C9: Prepare your data (index) | D9: Tous | E9: =COUNTIF('Mapping des pages'!$I$5:$I$218,B9) -> 2 | F9: =SUMIF('Mapping des pages'!$I$5:$I$218,B9,'Mapping des pages'!$F$5:$F$218) -> 3 | G9: =SUMIF('Mapping des pages'!$I$5:$I$218,B9,'Mapping des pages'!$N$5:$N$218) -> 2 | H9: =IF(E9=0,"Nouvelle page à écrire","Migration") -> Migration | I9: À valider
A10: Prepare your data | B10: /data/requirements/ | C10: Data requirements | D10: Tous | E10: =COUNTIF('Mapping des pages'!$I$5:$I$218,B10) -> 1 | F10: =SUMIF('Mapping des pages'!$I$5:$I$218,B10,'Mapping des pages'!$F$5:$F$218) -> 1 | G10: =SUMIF('Mapping des pages'!$I$5:$I$218,B10,'Mapping des pages'!$N$5:$N$218) -> 1 | H10: =IF(E10=0,"Nouvelle page à écrire","Migration") -> Migration | I10: À valider
A11: Prepare your data | B11: /data/connect-a-source/ | C11: Connect a source | D11: Web app | E11: =COUNTIF('Mapping des pages'!$I$5:$I$218,B11) -> 1 | F11: =SUMIF('Mapping des pages'!$I$5:$I$218,B11,'Mapping des pages'!$F$5:$F$218) -> 28 | G11: =SUMIF('Mapping des pages'!$I$5:$I$218,B11,'Mapping des pages'!$N$5:$N$218) -> 1 | H11: =IF(E11=0,"Nouvelle page à écrire","Migration") -> Migration | I11: À valider
A12: Prepare your data | B12: /data/connect-a-source/google-trends/ | C12: Connect a source › Google Trends | D12: Web app | E12: =COUNTIF('Mapping des pages'!$I$5:$I$218,B12) -> 1 | F12: =SUMIF('Mapping des pages'!$I$5:$I$218,B12,'Mapping des pages'!$F$5:$F$218) -> 4 | G12: =SUMIF('Mapping des pages'!$I$5:$I$218,B12,'Mapping des pages'!$N$5:$N$218) -> 1 | H12: =IF(E12=0,"Nouvelle page à écrire","Migration") -> Migration | I12: À valider
A13: Prepare your data | B13: /data/clean-and-transform/ | C13: Clean and transform | D13: Web app | E13: =COUNTIF('Mapping des pages'!$I$5:$I$218,B13) -> 3 | F13: =SUMIF('Mapping des pages'!$I$5:$I$218,B13,'Mapping des pages'!$F$5:$F$218) -> 44 | G13: =SUMIF('Mapping des pages'!$I$5:$I$218,B13,'Mapping des pages'!$N$5:$N$218) -> 2 | H13: =IF(E13=0,"Nouvelle page à écrire","Migration") -> Migration | I13: À valider
A14: Prepare your data | B14: /data/define-your-metrics/ | C14: Define your metrics | D14: Tous | E14: =COUNTIF('Mapping des pages'!$I$5:$I$218,B14) -> 5 | F14: =SUMIF('Mapping des pages'!$I$5:$I$218,B14,'Mapping des pages'!$F$5:$F$218) -> 14 | G14: =SUMIF('Mapping des pages'!$I$5:$I$218,B14,'Mapping des pages'!$N$5:$N$218) -> 5 | H14: =IF(E14=0,"Nouvelle page à écrire","Migration") -> Migration | I14: À valider
A15: Prepare your data | B15: /data/calendars/ | C15: Calendars | D15: Tous | E15: =COUNTIF('Mapping des pages'!$I$5:$I$218,B15) -> 6 | F15: =SUMIF('Mapping des pages'!$I$5:$I$218,B15,'Mapping des pages'!$F$5:$F$218) -> 25 | G15: =SUMIF('Mapping des pages'!$I$5:$I$218,B15,'Mapping des pages'!$N$5:$N$218) -> 6 | H15: =IF(E15=0,"Nouvelle page à écrire","Migration") -> Migration | I15: À valider
A16: Build a story | B16: /story/create-a-story/ | C16: Create a story | D16: Web app | E16: =COUNTIF('Mapping des pages'!$I$5:$I$218,B16) -> 1 | F16: =SUMIF('Mapping des pages'!$I$5:$I$218,B16,'Mapping des pages'!$F$5:$F$218) -> 2 | G16: =SUMIF('Mapping des pages'!$I$5:$I$218,B16,'Mapping des pages'!$N$5:$N$218) -> 1 | H16: =IF(E16=0,"Nouvelle page à écrire","Migration") -> Migration | I16: À valider
... A75: Legal (footer) | B75: /legal/privacy/looker-studio/ | C75: Privacy policy › Looker Studio | D75: Looker Studio | E75: =COUNTIF('Mapping des pages'!$I$5:$I$218,B75) -> 1 | F75: =SUMIF('Mapping des pages'!$I$5:$I$218,B75,'Mapping des pages'!$F$5:$F$218) -> 0 | G75: =SUMIF('Mapping des pages'!$I$5:$I$218,B75,'Mapping des pages'!$N$5:$N$218) -> 0 | H75: =IF(E75=0,"Nouvelle page à écrire","Migration") -> Migration | I75: À valider

Sheet Tips of the week
A1: Nettoyage des Tips of the week
A2: Proposition par tip : Garder / Archiver / À vérifier. La décision vaut pour la version EN et la version FR du même numéro. Archiver = retiré de la nouvelle doc (l’ancien fichier reste dans l’historique Git).
A4: N° | B4: Date | C4: Titre | D4: Version FR | E4: Proposition | F4: Raison | G4: Décision | H4: Commentaire | I4: Fichier (EN)
A5: 196 | B5: 2026-10-22 | C5: Tip of the week 196: Four keyboard shortcuts to speed up Datama Compare | D5: Oui | E5: Garder | F5: Tip récent sur une fonction actuelle | G5: Garder | I5: _posts/tips_of_the_week/2026-10-22-tip-of-the-week-196.md
A6: 195 | B6: 2026-10-15 | C6: Tip of the week 195: What If, test a scenario before you commit | D6: Oui | E6: Garder | F6: Tip récent sur une fonction actuelle | G6: Garder | I6: _posts/tips_of_the_week/2026-10-15-tip-of-the-week-195.md
A7: 194 | B7: 2026-10-08 | C7: Tip of the week 194: Make your waterfall look like your brand | D7: Oui | E7: Garder | F7: Tip récent sur une fonction actuelle | G7: Garder | I7: _posts/tips_of_the_week/2026-10-08-tip-of-the-week-194.md
A8: 193 | B8: 2026-10-01 | C8: Tip of the week 193: Explore your market equation with 'Sub-steps' | D8: Oui | E8: Garder | F8: Tip récent sur une fonction actuelle | G8: Garder | I8: _posts/tips_of_the_week/2026-10-01-tip-of-the-week-193.md
A9: 192 | B9: 2026-09-24 | C9: Tip of the week 192: Out of scope, Layer Source & more in Datama Extensions | D9: Oui | E9: Garder | F9: Tip récent sur une fonction actuelle | G9: Garder | I9: _posts/tips_of_the_week/2026-09-24-tip-of-the-week-192.md
A10: 191 | B10: 2026-09-17 | C10: Tip of the week 191: New features on the Compare extension | D10: Oui | E10: Garder | F10: Tip récent sur une fonction actuelle | G10: Garder | I10: _posts/tips_of_the_week/2026-09-17-tip-of-the-week-191.md
A11: 190 | B11: 2026-09-10 | C11: Tip of the week 190: Stage your waterfall story with 'Sub-pillars' | D11: Oui | E11: Garder | F11: Tip récent sur une fonction actuelle | G11: Garder | I11: _posts/tips_of_the_week/2026-09-10-tip-of-the-week-190.md
A12: 189 | B12: 2026-09-01 | C12: Tip of the week 189: The redesigned Datama Compare waterfall is here | D12: Oui | E12: Garder | F12: Tip récent sur une fonction actuelle | G12: Garder | I12: _posts/tips_of_the_week/2026-09-01-tip-of-the-week-189.md
A13: 188 | B13: 2026-08-06 | C13: Tip of the week 188: Interactive Datama extension in PowerPoint | D13: Oui | E13: Garder | F13: Tip récent sur une fonction actuelle | G13: Garder | I13: _posts/tips_of_the_week/2026-08-06-tip-of-the-week-188.md
A14: 187 | B14: 2026-07-30 | C14: Tip of the week 187: AI-powered Search | D14: Oui | E14: Garder | F14: Tip récent sur une fonction actuelle | G14: Garder | I14: _posts/tips_of_the_week/2026-07-30-tip-of-the-week-187.md
A15: 186 | B15: 2026-07-23 | C15: Tip of the week 186: More focused Extension Datama Detect | D15: Oui | E15: Garder | F15: Tip récent sur une fonction actuelle | G15: Garder | I15: _posts/tips_of_the_week/2026-07-23-tip-of-the-week-186.md
A16: 185 | B16: 2026-07-16 | C16: Tip of the week 185: How you can benefits from our latest features in your dataViz solutions ? | D16: Oui | E16: À vérifier | F16: Tip général sur les extensions : vérifier avec Studio | G16: À décider | I16: _posts/tips_of_the_week/2026-07-16-tip-of-the-week-185.md
... A56: 145 | B56: 2025-06-19 | C56: Tip of the week 145: Detect anomaly on segment of your data (available on Datama Light Extension) | D56: Oui | E56: À vérifier | F56: Vérifier que la fonction existe dans Studio | G56: À décider | I56: _posts/tips_of_the_week/2025-06-19-tip-of-the-week-145.md
A57: — | B57: 2025-06-12 | C57: 💡 New article: Handle missing values with Datama Fill-in! | D57: Non | E57: Archiver | F57: Pas un tip (annonce, article ou message) | G57: Archiver | I57: _posts/tips_of_the_week/2025-06-12-blog-article.md
A58: 144 | B58: 2025-05-22 | C58: Tip of the week 144: New functions available for calculated fields in Datama Prep! | D58: Oui | E58: À vérifier | F58: Vérifier que la fonction existe dans Studio | G58: À décider | I58: _posts/tips_of_the_week/2025-05-22-tip-of-the-week-144.md
A59: 143 | B59: 2025-04-23 | C59: Tip of the week 143: New source block in Prep: Table Connect | D59: Oui | E59: À vérifier | F59: Vérifier que la fonction existe dans Studio | G59: À décider | I59: _posts/tips_of_the_week/2025-04-23-tip-of-the-week-143.md
A60: 142 | B60: 2025-04-17 | C60: Tip of the week 142: (Reminder) CTRL + F 🔍 in Datama | D60: Oui | E60: Archiver | F60: Rappel du tip 88 | G60: Archiver | I60: _posts/tips_of_the_week/2025-04-17-tip-of-the-week-142.md
A61: 141 | B61: 2025-03-27 | C61: Tip of the week 141: Datama Prep «multiple date ranges» available for GA4 and Piano sources! | D61: Oui | E61: À vérifier | F61: Vérifier que la fonction existe dans Studio | G61: À décider | I61: _posts/tips_of_the_week/2025-03-27-tip-of-the-week-141.md
A62: — | B62: 2025-03-13 | C62: 🔔 [Reminder] Your opinion matters! | D62: Non | E62: Archiver | F62: Pas un tip (annonce, article ou message) | G62: Archiver | I62: _posts/tips_of_the_week/2025-03-13-reminder-NPS.md
A63: 139 | B63: 2025-02-27 | C63: 💬 Tell all to Datama chat! | D63: Oui | E63: À vérifier | F63: Vérifier que la fonction existe dans Studio | G63: À décider | I63: _posts/tips_of_the_week/2025-02-27-tip-of-the-week-139.md
A64: 138 | B64: 2025-02-13 | C64: New article on blog: (Re)Discover the mix effect with Datama Compare! | D64: Oui | E64: À vérifier | F64: Vérifier que la fonction existe dans Studio | G64: À décider | I64: _posts/tips_of_the_week/2025-02-13-tip-of-the-week-138.md
A65: 137 | B65: 2025-02-07 | C65: Tip of the week 137: New Views feature! | D65: Oui | E65: Archiver | F65: Les vues sont remplacées par les stories | G65: Archiver | I65: _posts/tips_of_the_week/2025-02-07-tip-of-the-week-137.md
A66: 136 | B66: 2025-01-30 | C66: Tip of the week 136: Use the Datama What if block to test your hypotheses! | D66: Oui | E66: Archiver | F66: Remplacé par le tip 195 (What If) | G66: Archiver | I66: _posts/tips_of_the_week/2025-01-30-tip-of-the-week-136.md
A67: 135 | B67: 2025-01-16 | C67: Tip of the week 135: New Journey Sankey visualization! | D67: Oui | E67: Garder | F67: Visualisation Journey toujours présente | G67: Garder | I67: _posts/tips_of_the_week/2025-01-16-tip-of-the-week-135.md
A68: 134 | B68: 2025-01-10 | C68: Tip of the week 134: See how far the analysis of just one metric can take you with Datama auto unpivot function! 🌟 | D68: Oui | E68: À vérifier | F68: Vérifier si la fonction existe dans Studio | G68: À décider | I68: _posts/tips_of_the_week/2025-01-10-tip-of-the-week-134.md
A69: — | B69: 2025-01-02 | C69: Datama wishes you a happy new year 2025! 🎇🎊 | D69: Non | E69: Archiver | F69: Pas un tip (annonce, article ou message) | G69: Archiver | I69: _posts/tips_of_the_week/2025-01-02-happy-new-year.md
A70: 133 | B70: 2024-12-20 | C70: Tip of the week 133: Optimize your data with the Datama Aggregation block! 🌟 | D70: Oui | E70: À vérifier | F70: Bloc Prep : vérifier dans Studio | G70: À décider | I70: _posts/tips_of_the_week/2024-12-20-tip-of-the-week-133.md
A71: 132 | B71: 2024-12-05 | C71: Tip of the Week 132: Cluster dimensions your way! | D71: Oui | E71: À vérifier | F71: Vérifier si la fonction existe dans Studio | G71: À décider | I71: _posts/tips_of_the_week/2024-12-05-tip-of-the-week-132.md
A72: 131 | B72: 2024-11-28 | C72: Tip of the Week 131: Datama is now Power BI visualization certified! | D72: Oui | E72: Archiver | F72: Annonce (certification Power BI) | G72: Archiver | I72: _posts/tips_of_the_week/2024-11-28-tip-of-the-week-131.md
A73: 130 | B73: 2024-11-07 | C73: Tip of the Week 130: Customize comments in your Datama extension! | D73: Oui | E73: Archiver | F73: Antérieur à 2025 : ancienne interface | G73: Archiver | I73: _posts/tips_of_the_week/2024-11-07-tip-of-the-week-130.md
A74: 129 | B74: 2024-10-31 | C74: Tip of the Week 129: Retrieve your Datama license keys and extension for your visualization tools 🔓 | D74: Oui | E74: Archiver | F74: Remplacé par les pages Environments | G74: Archiver | I74: _posts/tips_of_the_week/2024-10-31-tip-of-the-week-129.md
A75: 128 | B75: 2024-10-24 | C75: Tip of the Week 128: Organisation shared credentials 🗝️ | D75: Oui | E75: À vérifier | F75: Administration : vérifier le parcours dans Studio | G75: À décider | I75: _posts/tips_of_the_week/2024-10-24-tip-of-the-week-128.md
A76: 127 | B76: 2024-10-10 | C76: Tip of the Week 127: Detect anomalies faster than ever! 🌟 | D76: Oui | E76: À vérifier | F76: Vérifier si la fonction existe dans Studio | G76: À décider | I76: _posts/tips_of_the_week/2024-10-10-tip-of-the-week-127.md
A77: 126 | B77: 2024-10-03 | C77: Tip of the Week 126: Take advantage of Smart Interval for more accurate anomaly detection 📈 | D77: Oui | E77: Garder | F77: Méthode de détection toujours présente | G77: Garder | I77: _posts/tips_of_the_week/2024-10-03-tip-of-the-week-126.md
A78: 125 | B78: 2024-09-26 | C78: Tip of the Week 125: A new Radar Chart! | D78: Oui | E78: À vérifier | F78: Graphique Pivot : vérifier dans Studio | G78: À décider | I78: _posts/tips_of_the_week/2024-09-26-tip-of-the-week-125.md
A79: 124 | B79: 2024-09-19 | C79: Tip of the Week 124: Leverage our tips to simplify your analysis🌟 | D79: Oui | E79: Archiver | F79: Pas un tip | G79: Archiver | I79: _posts/tips_of_the_week/2024-09-19-tip-of-the-week-124.md
A80: — | B80: 2024-09-12 | C80: New article on blog: GA4 and BigQuery - Mind the Data Gaps!🚦 | D80: Non | E80: Archiver | F80: Pas un tip (annonce, article ou message) | G80: Archiver | I80: _posts/tips_of_the_week/2024-09-12-blog-article.md
...
